<robot name="room2">
    <link name="base_link"/>

    <link name="room">
      <visual>
        <geometry>
          <mesh filename="file:///home/serboba/rb_ws/src/robowflex/robowflex_dart/include/io/envs/room2/meshes/room.dae" scale=" 0.4 0.4 0.3"/>
        </geometry>
        <origin rpy="0 0 0" xyz="0 0 0"/>
      <material name="">
        <color rgba="0.94901960784 0.94901960784 0.94901960784 1"/>
      </material>
      </visual>

      <collision>
        <geometry>
          <mesh filename="file:///home/serboba/rb_ws/src/robowflex/robowflex_dart/include/io/envs/room2/meshes/room.dae" scale=" 0.4 0.4 0.3"/>
        </geometry>
        <origin rpy="0 0 0" xyz="0 0 0"/>       
       </collision>
    </link>


     <link name="link_0_joint_0">
      <visual>
        <geometry>
          <box size="0.1 0.8 1.1"/>
        </geometry>
        <origin rpy="0 0 0" xyz="0.0 0.4 0"/>
        <material name="">
          <color rgba="0.349019 0.470588 0.650980 1.0"/>
      </material>
      </visual>
      <collision>
        <geometry>
          <box size="0.1 0.8 1.1"/>
        </geometry>
        <origin rpy="0 0 0" xyz="0.0 0.4 0"/>     
       </collision>
    </link>


  <link name="link_1_joint_0">
      <visual>
        <geometry>
          <box size="0.1 0.8 1.1"/>
        </geometry>
        <origin rpy="0 0 0" xyz="0.0 0.4 0"/>
        <material name="">
          <color rgba="0.349019 0.470588 0.650980 1.0"/>
      </material>
      </visual>
      <collision>
        <geometry>
          <box size="0.1 0.8 1.1"/>
        </geometry>
        <origin rpy="0 0 0" xyz="0.0 0.4 0"/>     
       </collision>
    </link>


    <link name="link_2_joint_0">
      <visual>
        <geometry>
          <box size="0.5 0.5 0.75"/>
        </geometry>
        <origin rpy="0 0 0" xyz="0 0 0"/>
          <material name="">
          <color rgba="0.541176 0.156862 0.156862 1.0"/>
      </material>
      </visual>
      <collision>
        <geometry>
          <box size="0.5 0.5 0.75"/>
        </geometry>
        <origin rpy="0 0 0" xyz="0 0 0"/>      
       </collision>
    </link>
    

<link name="cube1_y_axis"/>


<joint name="room_j" type="fixed">
    <origin rpy="0 0 -1.57" xyz="0 0 0.0"/>
    <parent link="base_link"/>
    <child link="room"/>
    <axis xyz="0 1 0"/>
  </joint>

   <joint name="link_0_joint_0" type="revolute">
      <origin rpy="0 0 0" xyz="1.5 -1.25 0.55"/>
      <parent link="base_link"/>
      <child link="link_0_joint_0"/>
      <axis xyz="0 0 1"/>
      <limit lower="0" upper="1.57" effort="0.05" velocity="1.57"/>
  </joint>

   <joint name="link_1_joint_0" type="revolute">
      <origin rpy="0 0 0" xyz="-0.05 -1.25 0.55"/>
      <parent link="base_link"/>
      <child link="link_1_joint_0"/>
      <axis xyz="0 0 1"/>
      <limit lower="0" upper="1.57" effort="0.05" velocity="1.57"/>
  </joint>


  <joint name="link_2_joint_0" type="prismatic">
      <origin rpy="0 0 0" xyz="1.1 -0.8 0.375"/>
      <parent link="base_link"/>
      <child link="cube1_y_axis"/>
      <axis xyz="0 1 0"/>
      <limit lower="-1.40" upper="2.00" effort="0.05" velocity="1.57"/>
  </joint>


  <joint name="link_2_joint_1" type="prismatic">
      <origin rpy="0 0 0" xyz="0 0 0"/>
      <parent link="cube1_y_axis"/>
      <child link="link_2_joint_0"/>
      <axis xyz="1 0 0"/>
      <limit lower="-1.5" upper="3.00" effort="0.05" velocity="1.57"/>
  </joint>

  <link name="goal">
  <visual>
         <origin xyz="0 0 0" rpy="0 0 0" />
        <geometry>
          <cylinder radius="0.25" length="0.001" />
        </geometry>
        <material name="">
          <color rgba="0 1 0 1.0"/>
        </material>
      </visual>
</link>

<joint name = "goal" type="fixed">
  <origin rpy ="0 0 0" xyz="-0.7 0.7 0" />
  <parent link="base_link"/>
    <child link="goal"/>
</joint>



</robot>