<robot name="maze3">
    <link name="base_link"/>

    <link name="table">
      <visual>
        <geometry>
          <mesh filename="file:///home/serboba/rb_ws/src/robowflex/robowflex_dart/include/io/envs/maze3/meshes/maze3fixed2.dae" scale=" 0.750 0.750 0.750"/>
        </geometry>
        <origin rpy="0 0 0" xyz="0 0 0"/>

<material name="">
          <color rgba="0.87450980392 0.87450980392 0.87058823529 1.0"/>
      </material>

      </visual>
      <collision>
        <geometry>
          <mesh filename="file:///home/serboba/rb_ws/src/robowflex/robowflex_dart/include/io/envs/maze3/meshes/maze3fixed2.dae" scale=" 0.750 0.750 0.750"/>
        </geometry>
        <origin rpy="0 0 0" xyz="0 0 0"/>       
       </collision>
    </link>

    <link name="link_0_joint_0">
      <visual>
        <geometry>
          <box size="0.1 0.1 0.1"/>
        </geometry>
        <origin rpy="0 0 0" xyz="0 0 0"/>
      <material name="">
          <color rgba="0.0 0.8 0.0 1.0"/>
      </material>
      </visual>
      <collision>
        <geometry>
          <box size="0.1 0.1 0.1"/>
        </geometry>
        <origin rpy="0 0 0" xyz="0 0 0"/>       
       </collision>
    </link>


    <link name="cube_goal">
      <visual>
        <geometry>
          <box size="0.1 0.1 0.1"/>
        </geometry>
        <origin rpy="0 0 0" xyz="0 0 0"/>
      <material name="">
          <color rgba="0.0 0.8 0.0 0.4"/>
      </material>
      </visual>
    </link>


<link name="cube_x"/>


     <link name="link_1_joint_0">
      <visual>
        <geometry>
          <box size="0.35 0.025 0.16"/>
        </geometry>
        <origin rpy="0 0 0" xyz="0.0 0.0 0"/>
        <material name="">
          <color rgba="0.91372549019 0.39215686274 0.39215686274 1.0"/>
        </material>
      </visual>
      <collision>
        <geometry>
           <box size="0.35 0.025 0.16"/>
        </geometry>
        <origin rpy="0 0 0" xyz="0.0 0.0 0"/>
        </collision>
    </link>

     <link name="link_2_joint_0">
      <visual>
        <geometry>
          <box size="0.35 0.025 0.16"/>
        </geometry>
        <origin rpy="0 0 0" xyz="0.0 0.0 0"/>
        <material name="">
          <color rgba="0.91372549019 0.39215686274 0.39215686274 1.0"/>
        </material>
      </visual>
      <collision>
        <geometry>
           <box size="0.35 0.025 0.16"/>
        </geometry>
        <origin rpy="0 0 0" xyz="0.0 0.0 0"/>
        </collision>
    </link>

     <link name="link_3_joint_0">
      <visual>
        <geometry>
           <box size="0.35 0.025 0.16"/>
       </geometry>
        <origin rpy="0 0 0" xyz="0.0 0.0 0"/>
        <material name="">
          <color rgba="0.91372549019 0.39215686274 0.39215686274 1.0"/>
        </material>
      </visual>
      <collision>
        <geometry>
           <box size="0.35 0.025 0.16"/>
       </geometry>
        <origin rpy="0 0 0" xyz="0.0 0.0 0"/>
        </collision>
    </link>

         <link name="link_4_joint_0">
      <visual>
        <geometry>
           <box size="0.35 0.025 0.16"/>
       </geometry>
        <origin rpy="0 0 0" xyz="0.0 0.0 0"/>
        <material name="">
          <color rgba="0.91372549019 0.39215686274 0.39215686274 1.0"/>
        </material>
      </visual>
      <collision>
        <geometry>
           <box size="0.35 0.025 0.16"/>
       </geometry>
        <origin rpy="0 0 0" xyz="0.0 0.0 0"/>
        </collision>
    </link>


<joint name="table_j" type="fixed">
    <origin rpy="0 0 0" xyz="0.9 -0.4 0.73"/>
    <parent link="base_link"/>
    <child link="table"/>
    <axis xyz="0 1 0"/>
  </joint>

<joint name="goal" type="fixed">
    <origin rpy="0 0 0" xyz="1.26 0.05 0.86"/>
    <parent link="base_link"/>
    <child link="cube_goal"/>
</joint>

<joint name="link_0_joint_0" type="prismatic">
    <origin rpy="0 0 0" xyz="0.40 -0.9 0.86"/>
    <parent link="base_link"/>
    <child link="cube_x"/>
   <axis xyz="1 0 0"/>
  <limit lower="-0.07" upper="0.98" effort="0.05" velocity="1.57"/>
  </joint>


<joint name="link_0_joint_1" type="prismatic">
    <origin rpy="0 0 0" xyz="0.0 0 0.0"/>
    <parent link="cube_x"/>
    <child link="link_0_joint_0"/>
   <axis xyz="0 1 0"/>
  <limit lower="-0.1" upper="1.11" effort="0.05" velocity="1.57"/>
  </joint>


    <joint name="link_1_joint_0" type="prismatic">
        <origin rpy="0 0 0" xyz="0.46 -0.634 0.86"/>
        <parent link="base_link"/>
        <child link="link_1_joint_0"/>
        <axis xyz="1 0 0"/>
        <limit lower="0" upper="0.80" effort="5" velocity="1.57"/>
    </joint>

 <joint name="link_2_joint_0" type="prismatic">
    <origin rpy="0 0 0" xyz="0.46 -0.166 0.86"/>
        <parent link="base_link"/>
        <child link="link_2_joint_0"/>
        <axis xyz="1 0 0"/>
        <limit lower="0" upper="0.80" effort="5" velocity="1.57"/>
  </joint>


    <joint name="link_3_joint_0" type="prismatic">
        <origin rpy="0 0 0" xyz="1.24 -0.634 0.86"/>
        <parent link="base_link"/>
        <child link="link_3_joint_0"/>
        <axis xyz="1 0 0"/>
        <limit lower="-0.80" upper="0.0" effort="5" velocity="1.57"/>
    </joint>

 <joint name="link_4_joint_0" type="prismatic">
    <origin rpy="0 0 0" xyz="1.24 -0.166 0.86"/>
        <parent link="base_link"/>
        <child link="link_4_joint_0"/>
        <axis xyz="1 0 0"/>
        <limit lower="-0.80" upper="0.0" effort="5" velocity="1.57"/>
  </joint>


</robot>